Exception ignored in: <module 'threading' from '/usr/local/lib/python3.8/threading.py'>
Traceback (most recent call last):
  File "/usr/local/lib/python3.8/threading.py", line 1388, in _shutdown
    lock.acquire()
KeyboardInterrupt: 
Case has begun. Starting to handle exchange updates...
